Workbook
Name ExternalData_1: age!$A$1:$L$10000
Name ExternalData_2: income!$A$1:$K$7273
Name ExternalData_2: ref_age!$A$1:$B$7
Name ExternalData_2: ref_metric!$A$1:$A$3
Name ExternalData_3: ref_level!$A$1:$A$4
Name ExternalData_3: ref_location!$A$1:$B$8
Name ExternalData_3: regions!$A$1:$L$10909
Name ExternalData_4: ref_sex!$A$1:$A$4
Name ExternalData_5: ref_cause!$A$1:$A$206

Sheet Addendum
A1: Addendum
A2: Spreedsheet | B2: Description | C2: Updated On
A3: Age, Income, Regions | B3: It is important to note that these tables should be treated as independent data sets. Any calculations performed on similar groupings across tables may not yield consistent results. These are real-world examples. Regions is from World Health Organization member states; Income is from World Bank countries; Age includes data for countries and territories for which IHME has data. | C3: 45048
A4: ref_levels | B4: The levels in ref_levels sheet is described in a narrative manner in this same sheet and as follows. | C4: 45048
B5: The data is grouped into three levels: Level I, Level II and Level III. Level I represents the total of all health conditions. Level II groups individual conditions into categories. Level III presents each condition separately. In levels I and II, adjustment for comorbidity has been done. This means that people with more than one condition are counted only once. | C5: 45048
A6: ref_cause | B6: The column level was added. It signifies the level (of detail) of each cause. | C6: 45048
A7: ref_causegroups | B7: This is a new sheet and describes the grouping and hierarchy of the causes by level. | C7: 45048
A8: DataDictionary | B8: Included description of IncomeGroupCountries column for Age table | C8: 45048

Sheet DataDictionary
A1: English
B2: *data is expressed as decimal, please multiply by 100 to express as %; zero means there is no prevalence
B3: Sheet | C3: Column name | D3: Explanation | E3: Type
B4: Age table
C5: location_id | D5: Geographic scope | E5: Numeric code
C6: age_group_id | D6: Age range | E6: Numeric code
C7: age_group | D7: Age range | E7: text
C8: sex_id | D8: Sex | E8: Numeric code
C9: year_id | D9: Year of data collected | E9: Numeric code
C10: severity | D10: Severity | E10: Text
C11: metric_id | D11: Number or percentage of prevalence of disability | E11: Numeric code
C12: level | D12: Granularity of cause | E12: Numeric code
C13: cause_name | D13: Cause of disability | E13: Text
B14: * | C14: prev | D14: Prevalence of disability | E14: Decimal
B15: * | C15: lower | D15: Prevalence of disability, lower value of confidence interval | E15: Decimal
B16: * | C16: upper | D16: Prevalence of disability, upper value of confidence interval | E16: Decimal
B18: Income table
C19: income group countries | D19: World Bank income group classification of countries (July 2020) | E19: Text
C20: age_group_id | D20: Age range | E20: Numeric code
C21: sex_id | D21: Sex | E21: Numeric code
C22: year_id | D22: Year of data collected | E22: Numeric code
C23: cause_name | D23: Cause of disability | E23: Text
C24: level | D24: Granularity of cause | E24: Numeric code
C25: severity | D25: Severity | E25: Text
C26: metric_id | D26: Number or percentage | E26: Numeric code
B27: * | C27: mean | D27: Prevalence of disability, average | E27: Decimal
B28: * | C28: lower | D28: Prevalence of disability, lower value of confidence interval | E28: Decimal
B29: * | C29: upper | D29: Prevalence of disability, upper value of confidence interval | E29: Decimal
B31: Region table
C32: Region | D32: WHO regional scope | E32: Text
C33: location_id | D33: Geographic scope | E33: Numeric code
C34: age_group_id | D34: Age range | E34: Numeric code
C35: sex_id | D35: Sex | E35: Numeric code
C36: year_id | D36: Year of data collected | E36: Numeric code
C37: cause_name | D37: Cause of disability | E37: Text
C38: level | D38: Granularity of cause | E38: Numeric code
C39: severity | D39: Severity | E39: Text
C40: metric_id | D40: Number or percentage | E40: Numeric code
B41: * | C41: mean | D41: Prevalence of disability, average | E41: Decimal
B42: * | C42: lower | D42: Prevalence of disability, lower value of confidence interval | E42: Decimal
...

Sheet age
A1: location_id | B1: age_group_id | C1: age_group | D1: sex_id | E1: year_id | F1: severity | G1: metric_id | H1: level | I1: cause_name | J1: prev | K1: lower | L1: upper
A2: 1 | B2: NA | C2: 60 plus | D2: 1 | E2: 2021 | F2: moderate and severe | G2: 3 | H2: 3 | I2: Maternal obstructed labor and uterine rupture | J2: 0 | K2: 0 | L2: 0
A3: 1 | B3: NA | C3: 60 plus | D3: 1 | E3: 2021 | F3: moderate and severe | G3: 3 | H3: 3 | I3: Chlamydial infection | J3: 0 | K3: 0 | L3: 0
A4: 1 | B4: NA | C4: 60 plus | D4: 1 | E4: 2021 | F4: moderate and severe | G4: 3 | H4: 3 | I4: Gonococcal infection | J4: 0 | K4: 0 | L4: 0
A5: 1 | B5: NA | C5: 60 plus | D5: 1 | E5: 2021 | F5: moderate and severe | G5: 3 | H5: 3 | I5: Other sexually transmitted infections | J5: 0 | K5: 0 | L5: 0
A6: 1 | B6: NA | C6: 60 plus | D6: 1 | E6: 2021 | F6: moderate and severe | G6: 3 | H6: 3 | I6: Cervical cancer | J6: 0 | K6: 0 | L6: 0
A7: 1 | B7: NA | C7: 60 plus | D7: 1 | E7: 2021 | F7: moderate and severe | G7: 3 | H7: 3 | I7: Uterine cancer | J7: 0 | K7: 0 | L7: 0
A8: 1 | B8: NA | C8: 60 plus | D8: 1 | E8: 2021 | F8: moderate and severe | G8: 3 | H8: 3 | I8: Ovarian cancer | J8: 0 | K8: 0 | L8: 0
A9: 1 | B9: NA | C9: 60 plus | D9: 1 | E9: 2021 | F9: moderate and severe | G9: 3 | H9: 3 | I9: Anorexia nervosa | J9: 0 | K9: 0 | L9: 0
A10: 1 | B10: NA | C10: 60 plus | D10: 1 | E10: 2021 | F10: moderate and severe | G10: 3 | H10: 3 | I10: Bulimia nervosa | J10: 0 | K10: 0 | L10: 0
A11: 1 | B11: NA | C11: 60 plus | D11: 1 | E11: 2021 | F11: moderate and severe | G11: 3 | H11: 3 | I11: Conduct disorder | J11: 0 | K11: 0 | L11: 0
A12: 1 | B12: NA | C12: 60 plus | D12: 1 | E12: 2021 | F12: moderate and severe | G12: 3 | H12: 3 | I12: Other gynecological diseases | J12: 0 | K12: 0 | L12: 0
... A10000: 1 | B10000: NA | C10000: 60 plus | D10000: 3 | E10000: 2021 | F10000: severe | G10000: 1 | H10000: 1 | I10000: All causes | J10000: 31627575.34 | K10000: 26112109.5 | L10000: 39542734.77

Sheet income
A1: IncomeGroupCountry | B1: age_group_id | C1: sex_id | D1: year_id | E1: cause_name | F1: level | G1: severity | H1: metric_id | I1: mean | J1: lower | K1: upper
A2: High | B2: 22 | C2: 3 | D2: 2021 | E2: Upper respiratory infections | F2: 3 | G2: moderate and severe | H2: 3 | I2: 1.2707723e-05 | J2: 9.7583673e-06 | K2: 1.6101987e-05
A3: High | B3: 22 | C3: 3 | D3: 2021 | E3: Chagas disease | F3: 3 | G3: moderate and severe | H3: 3 | I3: 9.1583496e-06 | J3: 7.1364681e-06 | K3: 1.1285745e-05
A4: High | B4: 22 | C4: 3 | D4: 2021 | E4: Schistosomiasis | F4: 3 | G4: moderate and severe | H4: 3 | I4: 1.6070629e-08 | J4: 8.3859193e-09 | K4: 2.5265373e-08
A5: High | B5: 22 | C5: 3 | D5: 2021 | E5: Onchocerciasis | F5: 3 | G5: moderate and severe | H5: 3 | I5: 0 | J5: 0 | K5: 0
A6: High | B6: 22 | C6: 3 | D6: 2021 | E6: Trachoma | F6: 3 | G6: moderate and severe | H6: 3 | I6: 1.2357395e-06 | J6: 8.7919013e-07 | K6: 1.6793983e-06
A7: High | B7: 22 | C7: 3 | D7: 2021 | E7: Dengue | F7: 3 | G7: moderate and severe | H7: 3 | I7: 2.2141362e-05 | J7: 4.4311999e-06 | K7: 5.1672327e-05
A8: High | B8: 22 | C8: 3 | D8: 2021 | E8: Food-borne trematodiases | F8: 3 | G8: moderate and severe | H8: 3 | I8: 1.3542181e-07 | J8: 3.2773084e-08 | K8: 3.445428e-07
A9: High | B9: 22 | C9: 3 | D9: 2021 | E9: Iodine deficiency | F9: 3 | G9: moderate and severe | H9: 3 | I9: 2.4461826e-06 | J9: 6.4577431e-07 | K9: 3.5100444e-06
A10: High | B10: 22 | C10: 3 | D10: 2021 | E10: Vitamin A deficiency | F10: 3 | G10: moderate and severe | H10: 3 | I10: 2.3582422e-06 | J10: 1.7766279e-06 | K10: 3.0350253e-06
A11: High | B11: 22 | C11: 3 | D11: 2021 | E11: Other unspecified infectious diseases | F11: 3 | G11: moderate and severe | H11: 3 | I11: 2.7166321e-06 | J11: 1.9494426e-06 | K11: 3.812557e-06
A12: High | B12: 22 | C12: 3 | D12: 2021 | E12: Esophageal cancer | F12: 3 | G12: moderate and severe | H12: 3 | I12: 4.940873e-05 | J12: 4.4672416e-05 | K12: 5.1743484e-05
A13: High | B13: 22 | C13: 3 | D13: 2021 | E13: Stomach cancer | F13: 3 | G13: moderate and severe | H13: 3 | I13: 0.00011194745 | J13: 9.7384958e-05 | K13: 0.00011937081
... A7273: Upper middle | B7273: 22 | C7273: 3 | D7273: 2021 | E7273: All causes | F7273: 1 | G7273: severe | H7273: 1 | I7273: 46611950 | J7273: 39952593 | K7273: 55031310

Sheet regions
A1: Region | B1: location_id | C1: age_group_id | D1: sex_id | E1: year_id | F1: cause_name | G1: level | H1: severity | I1: metric_id | J1: mean | K1: lower | L1: upper | M1: level 2 cause | O1: Case ID
A2: AFR | B2: 44563 | C2: 22 | D2: 2 | E2: 2021 | F2: Chagas disease | G2: 3 | H2: moderate and severe | I2: 3 | J2: 0 | K2: 0 | L2: 0 | M2: =VLOOKUP(Table_3[[#This Row],[cause_name]],ref_causegroups!A:B,2,FALSE) -> Neglected tropical diseases and malaria | O2: 1
A3: AFR | B3: 44563 | C3: 22 | D3: 2 | E3: 2021 | F3: Food-borne trematodiases | G3: 3 | H3: moderate and severe | I3: 3 | J3: 0 | K3: 0 | L3: 0 | M3: =VLOOKUP(Table_3[[#This Row],[cause_name]],ref_causegroups!A:B,2,FALSE) -> Neglected tropical diseases and malaria | O3: 2
A4: AFR | B4: 44563 | C4: 22 | D4: 2 | E4: 2021 | F4: Zika virus | G4: 3 | H4: moderate and severe | I4: 3 | J4: 0 | K4: 0 | L4: 0 | M4: =VLOOKUP(Table_3[[#This Row],[cause_name]],ref_causegroups!A:B,2,FALSE) -> Neglected tropical diseases and malaria | O4: 3
A5: AFR | B5: 44563 | C5: 22 | D5: 2 | E5: 2021 | F5: Prostate cancer | G5: 3 | H5: moderate and severe | I5: 3 | J5: 0 | K5: 0 | L5: 0 | M5: =VLOOKUP(Table_3[[#This Row],[cause_name]],ref_causegroups!A:B,2,FALSE) -> Neoplasms | O5: 4
A6: AFR | B6: 44563 | C6: 22 | D6: 2 | E6: 2021 | F6: Testicular cancer | G6: 3 | H6: moderate and severe | I6: 3 | J6: 0 | K6: 0 | L6: 0 | M6: =VLOOKUP(Table_3[[#This Row],[cause_name]],ref_causegroups!A:B,2,FALSE) -> Neoplasms | O6: 5
A7: AFR | B7: 44563 | C7: 22 | D7: 2 | E7: 2021 | F7: Chagas disease | G7: 3 | H7: moderate and severe | I7: 1 | J7: 0 | K7: 0 | L7: 0 | M7: =VLOOKUP(Table_3[[#This Row],[cause_name]],ref_causegroups!A:B,2,FALSE) -> Neglected tropical diseases and malaria | O7: 6
A8: AFR | B8: 44563 | C8: 22 | D8: 2 | E8: 2021 | F8: Food-borne trematodiases | G8: 3 | H8: moderate and severe | I8: 1 | J8: 0 | K8: 0 | L8: 0 | M8: =VLOOKUP(Table_3[[#This Row],[cause_name]],ref_causegroups!A:B,2,FALSE) -> Neglected tropical diseases and malaria | O8: 7
A9: AFR | B9: 44563 | C9: 22 | D9: 2 | E9: 2021 | F9: Zika virus | G9: 3 | H9: moderate and severe | I9: 1 | J9: 0 | K9: 0 | L9: 0 | M9: =VLOOKUP(Table_3[[#This Row],[cause_name]],ref_causegroups!A:B,2,FALSE) -> Neglected tropical diseases and malaria | O9: 8
A10: AFR | B10: 44563 | C10: 22 | D10: 2 | E10: 2021 | F10: Prostate cancer | G10: 3 | H10: moderate and severe | I10: 1 | J10: 0 | K10: 0 | L10: 0 | M10: =VLOOKUP(Table_3[[#This Row],[cause_name]],ref_causegroups!A:B,2,FALSE) -> Neoplasms | O10: 9
A11: AFR | B11: 44563 | C11: 22 | D11: 2 | E11: 2021 | F11: Testicular cancer | G11: 3 | H11: moderate and severe | I11: 1 | J11: 0 | K11: 0 | L11: 0 | M11: =VLOOKUP(Table_3[[#This Row],[cause_name]],ref_causegroups!A:B,2,FALSE) -> Neoplasms | O11: 10
A12: AMR | B12: 44564 | C12: 22 | D12: 2 | E12: 2021 | F12: Maternal obstructed labor and uterine rupture | G12: 3 | H12: moderate and severe | I12: 3 | J12: 0 | K12: 0 | L12: 0 | M12: =VLOOKUP(Table_3[[#This Row],[cause_name]],ref_causegroups!A:B,2,FALSE) -> Maternal and neonatal disorders | O12: 11
A13: AMR | B13: 44564 | C13: 22 | D13: 2 | E13: 2021 | F13: Ebola | G13: 3 | H13: moderate and severe | I13: 3 | J13: 0 | K13: 0 | L13: 0 | M13: =VLOOKUP(Table_3[[#This Row],[cause_name]],ref_causegroups!A:B,2,FALSE) -> Neglected tropical diseases and malaria | O13: 12
... A9613: WPR | B9613: 44568 | C9613: 22 | D9613: 2 | E9613: 2021 | F9613: Testicular cancer | G9613: 3 | H9613: severe | I9613: 1 | J9613: 0 | K9613: 0 | L9613: 0 | M9613: =VLOOKUP(Table_3[[#This Row],[cause_name]],ref_causegroups!A:B,2,FALSE) -> Neoplasms | O9613: 9612
A9614: AFR | B9614: 44563 | C9614: 22 | D9614: 3 | E9614: 2021 | F9614: Skin and subcutaneous diseases | G9614: 2 | H9614: moderate and severe | I9614: 3 | J9614: 0.0047728602 | K9614: 0.0037313178 | L9614: 0.0059448998 | M9614: =Table_3[[#This Row],[cause_name]] -> Skin and subcutaneous diseases | O9614: 9613
A9615: AFR | B9615: 44563 | C9615: 22 | D9615: 3 | E9615: 2021 | F9615: Neoplasms | G9615: 2 | H9615: moderate and severe | I9615: 3 | J9615: 0.00038434801 | K9615: 0.00032667997 | L9615: 0.00042586783 | M9615: =Table_3[[#This Row],[cause_name]] -> Neoplasms | O9615: 9614
A9616: AFR | B9616: 44563 | C9616: 22 | D9616: 3 | E9616: 2021 | F9616: Neglected tropical diseases and malaria | G9616: 2 | H9616: moderate and severe | I9616: 3 | J9616: 0.0072081054 | K9616: 0.0053247757 | L9616: 0.0087724391 | M9616: =Table_3[[#This Row],[cause_name]] -> Neglected tropical diseases and malaria | O9616: 9615
A9617: AFR | B9617: 44563 | C9617: 22 | D9617: 3 | E9617: 2021 | F9617: Sense organ diseases | G9617: 2 | H9617: moderate and severe | I9617: 3 | J9617: 0.0085872639 | K9617: 0.0076865075 | L9617: 0.0096571913 | M9617: =Table_3[[#This Row],[cause_name]] -> Sense organ diseases | O9617: 9616
A9618: AFR | B9618: 44563 | C9618: 22 | D9618: 3 | E9618: 2021 | F9618: Substance use disorders | G9618: 2 | H9618: moderate and severe | I9618: 3 | J9618: 0.0017477971 | K9618: 0.0014590736 | L9618: 0.0020616436 | M9618: =Table_3[[#This Row],[cause_name]] -> Substance use disorders | O9618: 9617
A9619: AFR | B9619: 44563 | C9619: 22 | D9619: 3 | E9619: 2021 | F9619: Cardiovascular diseases | G9619: 2 | H9619: moderate and severe | I9619: 3 | J9619: 0.0052223553 | K9619: 0.0045332457 | L9619: 0.0058884264 | M9619: =Table_3[[#This Row],[cause_name]] -> Cardiovascular diseases | O9619: 9618
A9620: AFR | B9620: 44563 | C9620: 22 | D9620: 3 | E9620: 2021 | F9620: Neurological disorders | G9620: 2 | H9620: moderate and severe | I9620: 3 | J9620: 0.017484107 | K9620: 0.0090328667 | L9620: 0.028411317 | M9620: =Table_3[[#This Row],[cause_name]] -> Neurological disorders | O9620: 9619
A9621: AFR | B9621: 44563 | C9621: 22 | D9621: 3 | E9621: 2021 | F9621: Mental disorders | G9621: 2 | H9621: moderate and severe | I9621: 3 | J9621: 0.031479246 | K9621: 0.026052585 | L9621: 0.03688845 | M9621: =Table_3[[#This Row],[cause_name]] -> Mental disorders | O9621: 9620
A9622: AFR | B9622: 44563 | C9622: 22 | D9622: 3 | E9622: 2021 | F9622: Chronic respiratory diseases | G9622: 2 | H9622: moderate and severe | I9622: 3 | J9622: 0.0026616306 | K9622: 0.0022995206 | L9622: 0.0031341411 | M9622: =Table_3[[#This Row],[cause_name]] -> Chronic respiratory diseases | O9622: 9621
A9623: AFR | B9623: 44563 | C9623: 22 | D9623: 3 | E9623: 2021 | F9623: Respiratory infections and tuberculosis | G9623: 2 | H9623: moderate and severe | I9623: 3 | J9623: 0.010942715 | K9623: 0.0057787459 | L9623: 0.020737206 | M9623: =Table_3[[#This Row],[cause_name]] -> Respiratory infections and tuberculosis | O9623: 9622
A9624: AFR | B9624: 44563 | C9624: 22 | D9624: 3 | E9624: 2021 | F9624: Diabetes and kidney diseases | G9624: 2 | H9624: moderate and severe | I9624: 3 | J9624: 0.0010115385 | K9624: 0.00086845272 | L9624: 0.0011697616 | M9624: =Table_3[[#This Row],[cause_name]] -> Diabetes and kidney diseases | O9624: 9623
A9625: AFR | B9625: 44563 | C9625: 22 | D9625: 3 | E9625: 2021 | F9625: Digestive diseases | G9625: 2 | H9625: moderate and severe | I9625: 3 | J9625: 0.0008953337 | K9625: 0.00080915117 | L9625: 0.00099467941 | M9625: =Table_3[[#This Row],[cause_name]] -> Digestive diseases | O9625: 9624
... A10909: WPR | B10909: 44568 | C10909: 22 | D10909: 3 | E10909: 2021 | F10909: All causes | G10909: 1 | H10909: severe | I10909: 1 | J10909: 33481834 | K10909: 29011139 | L10909: 39150508 | M10909: =Table_3[[#This Row],[cause_name]] -> All causes | O10909: 10908

Sheet ref_location
A1: location_id | B1: Location
A2: 1 | B2: Global
A3: 44563 | B3: AFR
A4: 44564 | B4: AMR
A5: 44565 | B5: SEAR
A6: 44566 | B6: EUR
A7: 44567 | B7: EMR
A8: 44568 | B8: WPR

Sheet ref_age
A1: age_group_id | B1: age_group
A2: 22 | B2: All age
A3: 27 | B3: age standardized
A4: NA | B4: 60 plus
A5: NA | B5: 15 plus
A6: NA | B6: 0 to 14
A7: NA | B7: 15 to 59

Sheet ref_sex
A1: sex_id | B1: sex
A2: 1 | B2: males
A3: 2 | B3: females
A4: 3 | B4: both

Sheet ref_level
A1: level | B1: Level of detail
A2: 1 | B2: 1=all causes of disability
A3: 2 | B3: 2=groups of causes of disability, e.g. neurological disease or mental health diseases
A4: 3 | B4: 3=exact cause of disability, e.g. autism
D6: The data is grouped into three levels: Level I, Level II and Level III.
D8: Level I represents the total of all health conditions.
D9: Level II groups individual conditions into categories.
D10: Level III presents each condition separately.
D12: In levels I and II, adjustment for comorbidity has been done.
D13: This means that people with more than one condition are counted only once.

Sheet ref_metric
A1: metric_id | B1: Metric
A2: 1 | B2: Number
A3: 3 | B3: Percentage

Sheet ref_cause
A1: cause_name | B1: Level
A2: All causes | B2: 1
A3: Skin and subcutaneous diseases | B3: 2
A4: Neoplasms | B4: 2
A5: Neglected tropical diseases and malaria | B5: 2
A6: Sense organ diseases | B6: 2
A7: Substance use disorders | B7: 2
A8: Cardiovascular diseases | B8: 2
A9: Neurological disorders | B9: 2
A10: Mental disorders | B10: 2
A11: Chronic respiratory diseases | B11: 2
A12: Respiratory infections and tuberculosis | B12: 2
A13: HIV/AIDS and sexually transmitted infections | B13: 2
... A206: COVID-19 | B206: 3

Sheet ref_causegroups
A1: Level III | B1: Level II | C1: Level I
A2: Malaria | B2: Neglected tropical diseases and malaria | C2: All causes
A3: Chagas disease | B3: Neglected tropical diseases and malaria | C3: All causes
A4: African trypanosomiasis | B4: Neglected tropical diseases and malaria | C4: All causes
A5: Schistosomiasis | B5: Neglected tropical diseases and malaria | C5: All causes
A6: Cysticercosis | B6: Neglected tropical diseases and malaria | C6: All causes
A7: Cystic echinococcosis | B7: Neglected tropical diseases and malaria | C7: All causes
A8: Onchocerciasis | B8: Neglected tropical diseases and malaria | C8: All causes
A9: Trachoma | B9: Neglected tropical diseases and malaria | C9: All causes
A10: Dengue | B10: Neglected tropical diseases and malaria | C10: All causes
A11: Food-borne trematodiases | B11: Neglected tropical diseases and malaria | C11: All causes
A12: Ebola | B12: Neglected tropical diseases and malaria | C12: All causes
... A186: injuries | B186: Injuries | C186: All causes
